<?xml version="1.0" encoding="utf-8"?>
<!-- This URDF was automatically created by SolidWorks to URDF Exporter! Originally created by Stephen Brawner (brawner@gmail.com) 
     Commit Version: 1.6.0-4-g7f85cfe  Build Version: 1.6.7995.38578
     For more information, please see http://wiki.ros.org/sw_urdf_exporter -->
<robot
  name="rudolph_v4_3">
  <link
    name="base_link">
    <inertial>
      <origin
        xyz="0.101534961279229 -0.00437462913359959 0.0271443355632778"
        rpy="0 0 0" />
      <mass
        value="1.32414851074727" />
      <inertia
        ixx="0.00313096173401105"
        ixy="3.4234103262834E-06"
        ixz="-7.11526366576441E-07"
        iyy="0.00590529726535524"
        iyz="7.41837565599678E-07"
        izz="0.00899400568422118" />
    </inertial>
    <visual>
      <origin
        xyz="0 0 0"
        rpy="0 0 0" />
      <geometry>
        <mesh
          filename="package://rudolph_v4_3/meshes/base_link.STL" />
      </geometry>
      <material
        name="">
        <color
          rgba="0.792156862745098 0.819607843137255 0.933333333333333 1" />
      </material>
    </visual>
    <collision>
      <origin
        xyz="0 0 0"
        rpy="0 0 0" />
      <geometry>
        <mesh
          filename="package://rudolph_v4_3/meshes/base_link.STL" />
      </geometry>
    </collision>
  </link>
  <link
    name="base_laser">
    <inertial>
      <origin
        xyz="-0.00676641398454259 9.19718367893042E-05 -0.00981507539280288"
        rpy="0 0 0" />
      <mass
        value="1.33010751695787" />
      <inertia
        ixx="0.00061377057687069"
        ixy="-8.01970112250563E-07"
        ixz="-0.000158237807214438"
        iyy="0.000959131136457616"
        iyz="3.0936846683567E-06"
        izz="0.00109694905180103" />
    </inertial>
    <visual>
      <origin
        xyz="0 0 0"
        rpy="0 0 0" />
      <geometry>
        <mesh
          filename="package://rudolph_v4_3/meshes/base_laser.STL" />
      </geometry>
      <material
        name="">
        <color
          rgba="0.792156862745098 0.819607843137255 0.933333333333333 1" />
      </material>
    </visual>
    <collision>
      <origin
        xyz="0 0 0"
        rpy="0 0 0" />
      <geometry>
        <mesh
          filename="package://rudolph_v4_3/meshes/base_laser.STL" />
      </geometry>
    </collision>
  </link>
  <joint
    name="lidar"
    type="fixed">
    <origin
      xyz="0.1199 0 0.1271"
      rpy="0 0 0" />
    <parent
      link="base_link" />
    <child
      link="base_laser" />
    <axis
      xyz="0 0 0" />
  </joint>
  <link
    name="base_footprint">
    <inertial>
      <origin
        xyz="0.148863157194372 0.00135675454267504 0.0257699765847646"
        rpy="0 0 0" />
      <mass
        value="0.0160788172851309" />
      <inertia
        ixx="3.49316326388915E-06"
        ixy="-1.52832493190371E-07"
        ixz="-1.97171908375269E-22"
        iyy="6.29684776701663E-06"
        iyz="-4.91350569518991E-21"
        izz="3.48485677533925E-06" />
    </inertial>
    <visual>
      <origin
        xyz="0 0 0"
        rpy="0 0 0" />
      <geometry>
        <mesh
          filename="package://rudolph_v4_3/meshes/base_footprint.STL" />
      </geometry>
      <material
        name="">
        <color
          rgba="0.792156862745098 0.819607843137255 0.933333333333333 1" />
      </material>
    </visual>
    <collision>
      <origin
        xyz="0 0 0"
        rpy="0 0 0" />
      <geometry>
        <mesh
          filename="package://rudolph_v4_3/meshes/base_footprint.STL" />
      </geometry>
    </collision>
  </link>
  <joint
    name="foot_print"
    type="continuous">
    <origin
      xyz="0 0 -0.203869976584764"
      rpy="0 0 0" />
    <parent
      link="base_laser" />
    <child
      link="base_footprint" />
    <axis
      xyz="0.335999590456849 0.941862131743723 0" />
  </joint>
  <link
    name="right_wheel">
    <inertial>
      <origin
        xyz="2.33146835171283E-15 -0.000128187508022348 2.15105711021124E-16"
        rpy="0 0 0" />
      <mass
        value="0.0566666492820036" />
      <inertia
        ixx="2.86195955633458E-05"
        ixy="-1.45129517227166E-19"
        ixz="-9.67541169293159E-18"
        iyy="5.44361404566751E-05"
        iyz="-3.30558900894044E-20"
        izz="2.86195955633414E-05" />
    </inertial>
    <visual>
      <origin
        xyz="0 0 0"
        rpy="0 0 0" />
      <geometry>
        <mesh
          filename="package://rudolph_v4_3/meshes/right_wheel.STL" />
      </geometry>
      <material
        name="">
        <color
          rgba="0.792156862745098 0.819607843137255 0.933333333333333 1" />
      </material>
    </visual>
    <collision>
      <origin
        xyz="0 0 0"
        rpy="0 0 0" />
      <geometry>
        <mesh
          filename="package://rudolph_v4_3/meshes/right_wheel.STL" />
      </geometry>
    </collision>
  </link>
  <joint
    name="right"
    type="continuous">
    <origin
      xyz="0 0.11994 -0.03427"
      rpy="0 0 0" />
    <parent
      link="base_link" />
    <child
      link="right_wheel" />
    <axis
      xyz="0 1 0" />
  </joint>
  <link
    name="left_wheel">
    <inertial>
      <origin
        xyz="2.1094237467878E-15 0.000128187508022348 -8.43075609324728E-16"
        rpy="0 0 0" />
      <mass
        value="0.0566666492820037" />
      <inertia
        ixx="2.86195955633805E-05"
        ixy="1.60093518250458E-19"
        ixz="7.02426983460325E-18"
        iyy="5.44361404567349E-05"
        iyz="-5.39323227809156E-20"
        izz="2.86195955633666E-05" />
    </inertial>
    <visual>
      <origin
        xyz="0 0 0"
        rpy="0 0 0" />
      <geometry>
        <mesh
          filename="package://rudolph_v4_3/meshes/left_wheel.STL" />
      </geometry>
      <material
        name="">
        <color
          rgba="0.792156862745098 0.819607843137255 0.933333333333333 1" />
      </material>
    </visual>
    <collision>
      <origin
        xyz="0 0 0"
        rpy="0 0 0" />
      <geometry>
        <mesh
          filename="package://rudolph_v4_3/meshes/left_wheel.STL" />
      </geometry>
    </collision>
  </link>
  <joint
    name="left"
    type="continuous">
    <origin
      xyz="0 -0.11994 -0.03427"
      rpy="0 0 0" />
    <parent
      link="base_link" />
    <child
      link="left_wheel" />
    <axis
      xyz="0 1 0" />
  </joint>
</robot>